2025-09-11 19:55:27,758 - asyncio - ERROR - Task exception was never retrieved
future: <Task finished name='Task-261' coro=<WebSocketProtocol13.write_message.<locals>.wrapper() done, defined at C:\Users\Admin\AppData\Roaming\Python\Python312\site-packages\tornado\websocket.py:1111> exception=WebSocketClosedError()>
Traceback (most recent call last):
  File "C:\Users\Admin\AppData\Roaming\Python\Python312\site-packages\tornado\websocket.py", line 1113, in wrapper
    await fut
tornado.iostream.StreamClosedError: Stream is closed

During handling of the above exception, another exception occurred:

Traceback (most recent call last):
  File "C:\Users\Admin\AppData\Roaming\Python\Python312\site-packages\tornado\websocket.py", line 1115, in wrapper
    raise WebSocketClosedError()
tornado.websocket.WebSocketClosedError
