2025-09-09 21:35:46,020 - crm_dashboard - ERROR - Error: TransportError - HTTPSConnectionPool(host='oauth2.googleapis.com', port=443): Max retries exceeded with url: /token (Caused by NameResolutionError("<urllib3.connection.HTTPSConnection object at 0x0000023301CDCD10>: Failed to resolve 'oauth2.googleapis.com' ([Errno 11001] getaddrinfo failed)"))
Context: {'function': 'main', 'section': 'data_loading'}
Traceback: Traceback (most recent call last):
  File "C:\Users\Admin\AppData\Local\Programs\Python\Python312\Lib\site-packages\urllib3\connection.py", line 198, in _new_conn
    sock = connection.create_connection(
           ^^^^^^^^^^^^^^^^^^^^^^^^^^^^^
  File "C:\Users\Admin\AppData\Local\Programs\Python\Python312\Lib\site-packages\urllib3\util\connection.py", line 60, in create_connection
    for res in socket.getaddrinfo(host, port, family, socket.SOCK_STREAM):
               ^^^^^^^^^^^^^^^^^^^^^^^^^^^^^^^^^^^^^^^^^^^^^^^^^^^^^^^^^^
  File "C:\Users\Admin\AppData\Local\Programs\Python\Python312\Lib\socket.py", line 976, in getaddrinfo
    for res in _socket.getaddrinfo(host, port, family, type, proto, flags):
               ^^^^^^^^^^^^^^^^^^^^^^^^^^^^^^^^^^^^^^^^^^^^^^^^^^^^^^^^^^^
socket.gaierror: [Errno 11001] getaddrinfo failed

The above exception was the direct cause of the following exception:

Traceback (most recent call last):
  File "C:\Users\Admin\AppData\Local\Programs\Python\Python312\Lib\site-packages\urllib3\connectionpool.py", line 787, in urlopen
    response = self._make_request(
               ^^^^^^^^^^^^^^^^^^^
  File "C:\Users\Admin\AppData\Local\Programs\Python\Python312\Lib\site-packages\urllib3\connectionpool.py", line 488, in _make_request
    raise new_e
  File "C:\Users\Admin\AppData\Local\Programs\Python\Python312\Lib\site-packages\urllib3\connectionpool.py", line 464, in _make_request
    self._validate_conn(conn)
  File "C:\Users\Admin\AppData\Local\Programs\Python\Python312\Lib\site-packages\urllib3\connectionpool.py", line 1093, in _validate_conn
    conn.connect()
  File "C:\Users\Admin\AppData\Local\Programs\Python\Python312\Lib\site-packages\urllib3\connection.py", line 704, in connect
    self.sock = sock = self._new_conn()
                       ^^^^^^^^^^^^^^^^
  File "C:\Users\Admin\AppData\Local\Programs\Python\Python312\Lib\site-packages\urllib3\connection.py", line 205, in _new_conn
    raise NameResolutionError(self.host, self, e) from e
urllib3.exceptions.NameResolutionError: <urllib3.connection.HTTPSConnection object at 0x0000023301CDCD10>: Failed to resolve 'oauth2.googleapis.com' ([Errno 11001] getaddrinfo failed)

The above exception was the direct cause of the following exception:

Traceback (most recent call last):
  File "C:\Users\Admin\AppData\Local\Programs\Python\Python312\Lib\site-packages\requests\adapters.py", line 667, in send
    resp = conn.urlopen(
           ^^^^^^^^^^^^^
  File "C:\Users\Admin\AppData\Local\Programs\Python\Python312\Lib\site-packages\urllib3\connectionpool.py", line 841, in urlopen
    retries = retries.increment(
              ^^^^^^^^^^^^^^^^^^
  File "C:\Users\Admin\AppData\Local\Programs\Python\Python312\Lib\site-packages\urllib3\util\retry.py", line 519, in increment
    raise MaxRetryError(_pool, url, reason) from reason  # type: ignore[arg-type]
    ^^^^^^^^^^^^^^^^^^^^^^^^^^^^^^^^^^^^^^^^^^^^^^^^^^^
urllib3.exceptions.MaxRetryError: HTTPSConnectionPool(host='oauth2.googleapis.com', port=443): Max retries exceeded with url: /token (Caused by NameResolutionError("<urllib3.connection.HTTPSConnection object at 0x0000023301CDCD10>: Failed to resolve 'oauth2.googleapis.com' ([Errno 11001] getaddrinfo failed)"))

During handling of the above exception, another exception occurred:

Traceback (most recent call last):
  File "C:\Users\Admin\AppData\Local\Programs\Python\Python312\Lib\site-packages\google\auth\transport\requests.py", line 187, in __call__
    response = self.session.request(
               ^^^^^^^^^^^^^^^^^^^^^
  File "C:\Users\Admin\AppData\Local\Programs\Python\Python312\Lib\site-packages\requests\sessions.py", line 589, in request
    resp = self.send(prep, **send_kwargs)
           ^^^^^^^^^^^^^^^^^^^^^^^^^^^^^^
  File "C:\Users\Admin\AppData\Local\Programs\Python\Python312\Lib\site-packages\requests\sessions.py", line 703, in send
    r = adapter.send(request, **kwargs)
        ^^^^^^^^^^^^^^^^^^^^^^^^^^^^^^^
  File "C:\Users\Admin\AppData\Local\Programs\Python\Python312\Lib\site-packages\requests\adapters.py", line 700, in send
    raise ConnectionError(e, request=request)
requests.exceptions.ConnectionError: HTTPSConnectionPool(host='oauth2.googleapis.com', port=443): Max retries exceeded with url: /token (Caused by NameResolutionError("<urllib3.connection.HTTPSConnection object at 0x0000023301CDCD10>: Failed to resolve 'oauth2.googleapis.com' ([Errno 11001] getaddrinfo failed)"))

The above exception was the direct cause of the following exception:

Traceback (most recent call last):
  File "F:\C_S\pages\1_dashboard.py", line 76, in main
    dataframes = load_all_data()
                 ^^^^^^^^^^^^^^^
  File "F:\C_S\process\data_loader.py", line 38, in load_all_data
    dataframes = load_tables_from_drive(all_tables)
                 ^^^^^^^^^^^^^^^^^^^^^^^^^^^^^^^^^^
  File "F:\C_S\lode_data\load_data_in_drive.py", line 138, in load_tables_from_drive
    st.session_state.dataframes = lode_drive()
                                  ^^^^^^^^^^^^
  File "F:\C_S\lode_data\load_data_in_drive.py", line 108, in lode_drive
    service = get_drive_service()
              ^^^^^^^^^^^^^^^^^^^
  File "F:\C_S\lode_data\load_data_in_drive.py", line 20, in get_drive_service
    creds.refresh(Request())
  File "C:\Users\Admin\AppData\Local\Programs\Python\Python312\Lib\site-packages\google\oauth2\credentials.py", line 409, in refresh
    ) = reauth.refresh_grant(
        ^^^^^^^^^^^^^^^^^^^^^
  File "C:\Users\Admin\AppData\Local\Programs\Python\Python312\Lib\site-packages\google\oauth2\reauth.py", line 333, in refresh_grant
    response_status_ok, response_data, retryable_error = _client._token_endpoint_request_no_throw(
                                                         ^^^^^^^^^^^^^^^^^^^^^^^^^^^^^^^^^^^^^^^^^
  File "C:\Users\Admin\AppData\Local\Programs\Python\Python312\Lib\site-packages\google\oauth2\_client.py", line 192, in _token_endpoint_request_no_throw
    response = request(
               ^^^^^^^^
  File "C:\Users\Admin\AppData\Local\Programs\Python\Python312\Lib\site-packages\google\auth\transport\requests.py", line 194, in __call__
    raise new_exc from caught_exc
google.auth.exceptions.TransportError: HTTPSConnectionPool(host='oauth2.googleapis.com', port=443): Max retries exceeded with url: /token (Caused by NameResolutionError("<urllib3.connection.HTTPSConnection object at 0x0000023301CDCD10>: Failed to resolve 'oauth2.googleapis.com' ([Errno 11001] getaddrinfo failed)"))

2025-09-09 21:36:05,893 - crm_dashboard - ERROR - Error: TransportError - HTTPSConnectionPool(host='oauth2.googleapis.com', port=443): Max retries exceeded with url: /token (Caused by NameResolutionError("<urllib3.connection.HTTPSConnection object at 0x0000023301CDD910>: Failed to resolve 'oauth2.googleapis.com' ([Errno 11001] getaddrinfo failed)"))
Context: {'function': 'main', 'section': 'data_loading'}
Traceback: Traceback (most recent call last):
  File "C:\Users\Admin\AppData\Local\Programs\Python\Python312\Lib\site-packages\urllib3\connection.py", line 198, in _new_conn
    sock = connection.create_connection(
           ^^^^^^^^^^^^^^^^^^^^^^^^^^^^^
  File "C:\Users\Admin\AppData\Local\Programs\Python\Python312\Lib\site-packages\urllib3\util\connection.py", line 60, in create_connection
    for res in socket.getaddrinfo(host, port, family, socket.SOCK_STREAM):
               ^^^^^^^^^^^^^^^^^^^^^^^^^^^^^^^^^^^^^^^^^^^^^^^^^^^^^^^^^^
  File "C:\Users\Admin\AppData\Local\Programs\Python\Python312\Lib\socket.py", line 976, in getaddrinfo
    for res in _socket.getaddrinfo(host, port, family, type, proto, flags):
               ^^^^^^^^^^^^^^^^^^^^^^^^^^^^^^^^^^^^^^^^^^^^^^^^^^^^^^^^^^^
socket.gaierror: [Errno 11001] getaddrinfo failed

The above exception was the direct cause of the following exception:

Traceback (most recent call last):
  File "C:\Users\Admin\AppData\Local\Programs\Python\Python312\Lib\site-packages\urllib3\connectionpool.py", line 787, in urlopen
    response = self._make_request(
               ^^^^^^^^^^^^^^^^^^^
  File "C:\Users\Admin\AppData\Local\Programs\Python\Python312\Lib\site-packages\urllib3\connectionpool.py", line 488, in _make_request
    raise new_e
  File "C:\Users\Admin\AppData\Local\Programs\Python\Python312\Lib\site-packages\urllib3\connectionpool.py", line 464, in _make_request
    self._validate_conn(conn)
  File "C:\Users\Admin\AppData\Local\Programs\Python\Python312\Lib\site-packages\urllib3\connectionpool.py", line 1093, in _validate_conn
    conn.connect()
  File "C:\Users\Admin\AppData\Local\Programs\Python\Python312\Lib\site-packages\urllib3\connection.py", line 704, in connect
    self.sock = sock = self._new_conn()
                       ^^^^^^^^^^^^^^^^
  File "C:\Users\Admin\AppData\Local\Programs\Python\Python312\Lib\site-packages\urllib3\connection.py", line 205, in _new_conn
    raise NameResolutionError(self.host, self, e) from e
urllib3.exceptions.NameResolutionError: <urllib3.connection.HTTPSConnection object at 0x0000023301CDD910>: Failed to resolve 'oauth2.googleapis.com' ([Errno 11001] getaddrinfo failed)

The above exception was the direct cause of the following exception:

Traceback (most recent call last):
  File "C:\Users\Admin\AppData\Local\Programs\Python\Python312\Lib\site-packages\requests\adapters.py", line 667, in send
    resp = conn.urlopen(
           ^^^^^^^^^^^^^
  File "C:\Users\Admin\AppData\Local\Programs\Python\Python312\Lib\site-packages\urllib3\connectionpool.py", line 841, in urlopen
    retries = retries.increment(
              ^^^^^^^^^^^^^^^^^^
  File "C:\Users\Admin\AppData\Local\Programs\Python\Python312\Lib\site-packages\urllib3\util\retry.py", line 519, in increment
    raise MaxRetryError(_pool, url, reason) from reason  # type: ignore[arg-type]
    ^^^^^^^^^^^^^^^^^^^^^^^^^^^^^^^^^^^^^^^^^^^^^^^^^^^
urllib3.exceptions.MaxRetryError: HTTPSConnectionPool(host='oauth2.googleapis.com', port=443): Max retries exceeded with url: /token (Caused by NameResolutionError("<urllib3.connection.HTTPSConnection object at 0x0000023301CDD910>: Failed to resolve 'oauth2.googleapis.com' ([Errno 11001] getaddrinfo failed)"))

During handling of the above exception, another exception occurred:

Traceback (most recent call last):
  File "C:\Users\Admin\AppData\Local\Programs\Python\Python312\Lib\site-packages\google\auth\transport\requests.py", line 187, in __call__
    response = self.session.request(
               ^^^^^^^^^^^^^^^^^^^^^
  File "C:\Users\Admin\AppData\Local\Programs\Python\Python312\Lib\site-packages\requests\sessions.py", line 589, in request
    resp = self.send(prep, **send_kwargs)
           ^^^^^^^^^^^^^^^^^^^^^^^^^^^^^^
  File "C:\Users\Admin\AppData\Local\Programs\Python\Python312\Lib\site-packages\requests\sessions.py", line 703, in send
    r = adapter.send(request, **kwargs)
        ^^^^^^^^^^^^^^^^^^^^^^^^^^^^^^^
  File "C:\Users\Admin\AppData\Local\Programs\Python\Python312\Lib\site-packages\requests\adapters.py", line 700, in send
    raise ConnectionError(e, request=request)
requests.exceptions.ConnectionError: HTTPSConnectionPool(host='oauth2.googleapis.com', port=443): Max retries exceeded with url: /token (Caused by NameResolutionError("<urllib3.connection.HTTPSConnection object at 0x0000023301CDD910>: Failed to resolve 'oauth2.googleapis.com' ([Errno 11001] getaddrinfo failed)"))

The above exception was the direct cause of the following exception:

Traceback (most recent call last):
  File "F:\C_S\pages\1_dashboard.py", line 76, in main
    dataframes = load_all_data()
                 ^^^^^^^^^^^^^^^
  File "F:\C_S\process\data_loader.py", line 38, in load_all_data
    dataframes = load_tables_from_drive(all_tables)
                 ^^^^^^^^^^^^^^^^^^^^^^^^^^^^^^^^^^
  File "F:\C_S\lode_data\load_data_in_drive.py", line 138, in load_tables_from_drive
    st.session_state.dataframes = lode_drive()
                                  ^^^^^^^^^^^^
  File "F:\C_S\lode_data\load_data_in_drive.py", line 108, in lode_drive
    service = get_drive_service()
              ^^^^^^^^^^^^^^^^^^^
  File "F:\C_S\lode_data\load_data_in_drive.py", line 20, in get_drive_service
    creds.refresh(Request())
  File "C:\Users\Admin\AppData\Local\Programs\Python\Python312\Lib\site-packages\google\oauth2\credentials.py", line 409, in refresh
    ) = reauth.refresh_grant(
        ^^^^^^^^^^^^^^^^^^^^^
  File "C:\Users\Admin\AppData\Local\Programs\Python\Python312\Lib\site-packages\google\oauth2\reauth.py", line 333, in refresh_grant
    response_status_ok, response_data, retryable_error = _client._token_endpoint_request_no_throw(
                                                         ^^^^^^^^^^^^^^^^^^^^^^^^^^^^^^^^^^^^^^^^^
  File "C:\Users\Admin\AppData\Local\Programs\Python\Python312\Lib\site-packages\google\oauth2\_client.py", line 192, in _token_endpoint_request_no_throw
    response = request(
               ^^^^^^^^
  File "C:\Users\Admin\AppData\Local\Programs\Python\Python312\Lib\site-packages\google\auth\transport\requests.py", line 194, in __call__
    raise new_exc from caught_exc
google.auth.exceptions.TransportError: HTTPSConnectionPool(host='oauth2.googleapis.com', port=443): Max retries exceeded with url: /token (Caused by NameResolutionError("<urllib3.connection.HTTPSConnection object at 0x0000023301CDD910>: Failed to resolve 'oauth2.googleapis.com' ([Errno 11001] getaddrinfo failed)"))

2025-09-09 21:36:07,709 - crm_dashboard - ERROR - Error: TransportError - HTTPSConnectionPool(host='oauth2.googleapis.com', port=443): Max retries exceeded with url: /token (Caused by NameResolutionError("<urllib3.connection.HTTPSConnection object at 0x00000233024FB890>: Failed to resolve 'oauth2.googleapis.com' ([Errno 11001] getaddrinfo failed)"))
Context: {'function': 'main', 'section': 'data_loading'}
Traceback: Traceback (most recent call last):
  File "C:\Users\Admin\AppData\Local\Programs\Python\Python312\Lib\site-packages\urllib3\connection.py", line 198, in _new_conn
    sock = connection.create_connection(
           ^^^^^^^^^^^^^^^^^^^^^^^^^^^^^
  File "C:\Users\Admin\AppData\Local\Programs\Python\Python312\Lib\site-packages\urllib3\util\connection.py", line 60, in create_connection
    for res in socket.getaddrinfo(host, port, family, socket.SOCK_STREAM):
               ^^^^^^^^^^^^^^^^^^^^^^^^^^^^^^^^^^^^^^^^^^^^^^^^^^^^^^^^^^
  File "C:\Users\Admin\AppData\Local\Programs\Python\Python312\Lib\socket.py", line 976, in getaddrinfo
    for res in _socket.getaddrinfo(host, port, family, type, proto, flags):
               ^^^^^^^^^^^^^^^^^^^^^^^^^^^^^^^^^^^^^^^^^^^^^^^^^^^^^^^^^^^
socket.gaierror: [Errno 11001] getaddrinfo failed

The above exception was the direct cause of the following exception:

Traceback (most recent call last):
  File "C:\Users\Admin\AppData\Local\Programs\Python\Python312\Lib\site-packages\urllib3\connectionpool.py", line 787, in urlopen
    response = self._make_request(
               ^^^^^^^^^^^^^^^^^^^
  File "C:\Users\Admin\AppData\Local\Programs\Python\Python312\Lib\site-packages\urllib3\connectionpool.py", line 488, in _make_request
    raise new_e
  File "C:\Users\Admin\AppData\Local\Programs\Python\Python312\Lib\site-packages\urllib3\connectionpool.py", line 464, in _make_request
    self._validate_conn(conn)
  File "C:\Users\Admin\AppData\Local\Programs\Python\Python312\Lib\site-packages\urllib3\connectionpool.py", line 1093, in _validate_conn
    conn.connect()
  File "C:\Users\Admin\AppData\Local\Programs\Python\Python312\Lib\site-packages\urllib3\connection.py", line 704, in connect
    self.sock = sock = self._new_conn()
                       ^^^^^^^^^^^^^^^^
  File "C:\Users\Admin\AppData\Local\Programs\Python\Python312\Lib\site-packages\urllib3\connection.py", line 205, in _new_conn
    raise NameResolutionError(self.host, self, e) from e
urllib3.exceptions.NameResolutionError: <urllib3.connection.HTTPSConnection object at 0x00000233024FB890>: Failed to resolve 'oauth2.googleapis.com' ([Errno 11001] getaddrinfo failed)

The above exception was the direct cause of the following exception:

Traceback (most recent call last):
  File "C:\Users\Admin\AppData\Local\Programs\Python\Python312\Lib\site-packages\requests\adapters.py", line 667, in send
    resp = conn.urlopen(
           ^^^^^^^^^^^^^
  File "C:\Users\Admin\AppData\Local\Programs\Python\Python312\Lib\site-packages\urllib3\connectionpool.py", line 841, in urlopen
    retries = retries.increment(
              ^^^^^^^^^^^^^^^^^^
  File "C:\Users\Admin\AppData\Local\Programs\Python\Python312\Lib\site-packages\urllib3\util\retry.py", line 519, in increment
    raise MaxRetryError(_pool, url, reason) from reason  # type: ignore[arg-type]
    ^^^^^^^^^^^^^^^^^^^^^^^^^^^^^^^^^^^^^^^^^^^^^^^^^^^
urllib3.exceptions.MaxRetryError: HTTPSConnectionPool(host='oauth2.googleapis.com', port=443): Max retries exceeded with url: /token (Caused by NameResolutionError("<urllib3.connection.HTTPSConnection object at 0x00000233024FB890>: Failed to resolve 'oauth2.googleapis.com' ([Errno 11001] getaddrinfo failed)"))

During handling of the above exception, another exception occurred:

Traceback (most recent call last):
  File "C:\Users\Admin\AppData\Local\Programs\Python\Python312\Lib\site-packages\google\auth\transport\requests.py", line 187, in __call__
    response = self.session.request(
               ^^^^^^^^^^^^^^^^^^^^^
  File "C:\Users\Admin\AppData\Local\Programs\Python\Python312\Lib\site-packages\requests\sessions.py", line 589, in request
    resp = self.send(prep, **send_kwargs)
           ^^^^^^^^^^^^^^^^^^^^^^^^^^^^^^
  File "C:\Users\Admin\AppData\Local\Programs\Python\Python312\Lib\site-packages\requests\sessions.py", line 703, in send
    r = adapter.send(request, **kwargs)
        ^^^^^^^^^^^^^^^^^^^^^^^^^^^^^^^
  File "C:\Users\Admin\AppData\Local\Programs\Python\Python312\Lib\site-packages\requests\adapters.py", line 700, in send
    raise ConnectionError(e, request=request)
requests.exceptions.ConnectionError: HTTPSConnectionPool(host='oauth2.googleapis.com', port=443): Max retries exceeded with url: /token (Caused by NameResolutionError("<urllib3.connection.HTTPSConnection object at 0x00000233024FB890>: Failed to resolve 'oauth2.googleapis.com' ([Errno 11001] getaddrinfo failed)"))

The above exception was the direct cause of the following exception:

Traceback (most recent call last):
  File "F:\C_S\pages\1_dashboard.py", line 76, in main
    dataframes = load_all_data()
                 ^^^^^^^^^^^^^^^
  File "F:\C_S\process\data_loader.py", line 38, in load_all_data
    dataframes = load_tables_from_drive(all_tables)
                 ^^^^^^^^^^^^^^^^^^^^^^^^^^^^^^^^^^
  File "F:\C_S\lode_data\load_data_in_drive.py", line 138, in load_tables_from_drive
    st.session_state.dataframes = lode_drive()
                                  ^^^^^^^^^^^^
  File "F:\C_S\lode_data\load_data_in_drive.py", line 108, in lode_drive
    service = get_drive_service()
              ^^^^^^^^^^^^^^^^^^^
  File "F:\C_S\lode_data\load_data_in_drive.py", line 20, in get_drive_service
    creds.refresh(Request())
  File "C:\Users\Admin\AppData\Local\Programs\Python\Python312\Lib\site-packages\google\oauth2\credentials.py", line 409, in refresh
    ) = reauth.refresh_grant(
        ^^^^^^^^^^^^^^^^^^^^^
  File "C:\Users\Admin\AppData\Local\Programs\Python\Python312\Lib\site-packages\google\oauth2\reauth.py", line 333, in refresh_grant
    response_status_ok, response_data, retryable_error = _client._token_endpoint_request_no_throw(
                                                         ^^^^^^^^^^^^^^^^^^^^^^^^^^^^^^^^^^^^^^^^^
  File "C:\Users\Admin\AppData\Local\Programs\Python\Python312\Lib\site-packages\google\oauth2\_client.py", line 192, in _token_endpoint_request_no_throw
    response = request(
               ^^^^^^^^
  File "C:\Users\Admin\AppData\Local\Programs\Python\Python312\Lib\site-packages\google\auth\transport\requests.py", line 194, in __call__
    raise new_exc from caught_exc
google.auth.exceptions.TransportError: HTTPSConnectionPool(host='oauth2.googleapis.com', port=443): Max retries exceeded with url: /token (Caused by NameResolutionError("<urllib3.connection.HTTPSConnection object at 0x00000233024FB890>: Failed to resolve 'oauth2.googleapis.com' ([Errno 11001] getaddrinfo failed)"))

